Traceback (most recent call last):
  File "/usr/lib/python3.6/asyncio/base_events.py", line 1043, in create_server
    sock.bind(sa)
OSError: [Errno 98] Address already in use

During handling of the above exception, another exception occurred:

Traceback (most recent call last):
  File "server.py", line 97, in <module>
    web.run_app(app, host=ip_addr, port=port)
  File "/usr/lib/python3.6/site-packages/aiohttp/web.py", line 399, in run_app
    asyncio.gather(*server_creations, loop=loop)
  File "/usr/lib/python3.6/asyncio/base_events.py", line 466, in run_until_complete
    return future.result()
  File "/usr/lib/python3.6/asyncio/base_events.py", line 1047, in create_server
    % (sa, err.strerror.lower()))
OSError: [Errno 98] error while attempting to bind on address ('0.0.0.0', 8080): address already in use
Traceback (most recent call last):
  File "/usr/lib/python3.6/asyncio/base_events.py", line 1043, in create_server
    sock.bind(sa)
OSError: [Errno 98] Address already in use

During handling of the above exception, another exception occurred:

Traceback (most recent call last):
  File "server.py", line 97, in <module>
    web.run_app(app, host=ip_addr, port=port)
  File "/usr/lib/python3.6/site-packages/aiohttp/web.py", line 399, in run_app
    asyncio.gather(*server_creations, loop=loop)
  File "/usr/lib/python3.6/asyncio/base_events.py", line 466, in run_until_complete
    return future.result()
  File "/usr/lib/python3.6/asyncio/base_events.py", line 1047, in create_server
    % (sa, err.strerror.lower()))
OSError: [Errno 98] error while attempting to bind on address ('0.0.0.0', 8080): address already in use
Traceback (most recent call last):
  File "/usr/lib/python3.6/asyncio/base_events.py", line 1043, in create_server
    sock.bind(sa)
OSError: [Errno 98] Address already in use

During handling of the above exception, another exception occurred:

Traceback (most recent call last):
  File "server.py", line 97, in <module>
    web.run_app(app, host=ip_addr, port=port)
  File "/usr/lib/python3.6/site-packages/aiohttp/web.py", line 399, in run_app
    asyncio.gather(*server_creations, loop=loop)
  File "/usr/lib/python3.6/asyncio/base_events.py", line 466, in run_until_complete
    return future.result()
  File "/usr/lib/python3.6/asyncio/base_events.py", line 1047, in create_server
    % (sa, err.strerror.lower()))
OSError: [Errno 98] error while attempting to bind on address ('0.0.0.0', 8080): address already in use
Traceback (most recent call last):
  File "/usr/lib/python3.6/asyncio/base_events.py", line 1043, in create_server
    sock.bind(sa)
OSError: [Errno 98] Address already in use

During handling of the above exception, another exception occurred:

Traceback (most recent call last):
  File "server.py", line 97, in <module>
    web.run_app(app, host=ip_addr, port=port)
  File "/usr/lib/python3.6/site-packages/aiohttp/web.py", line 399, in run_app
    asyncio.gather(*server_creations, loop=loop)
  File "/usr/lib/python3.6/asyncio/base_events.py", line 466, in run_until_complete
    return future.result()
  File "/usr/lib/python3.6/asyncio/base_events.py", line 1047, in create_server
    % (sa, err.strerror.lower()))
OSError: [Errno 98] error while attempting to bind on address ('0.0.0.0', 8080): address already in use
Traceback (most recent call last):
  File "/usr/lib/python3.6/asyncio/base_events.py", line 1043, in create_server
    sock.bind(sa)
OSError: [Errno 98] Address already in use

During handling of the above exception, another exception occurred:

Traceback (most recent call last):
  File "server.py", line 97, in <module>
    web.run_app(app, host=ip_addr, port=port)
  File "/usr/lib/python3.6/site-packages/aiohttp/web.py", line 399, in run_app
    asyncio.gather(*server_creations, loop=loop)
  File "/usr/lib/python3.6/asyncio/base_events.py", line 466, in run_until_complete
    return future.result()
  File "/usr/lib/python3.6/asyncio/base_events.py", line 1047, in create_server
    % (sa, err.strerror.lower()))
OSError: [Errno 98] error while attempting to bind on address ('0.0.0.0', 8080): address already in use
Traceback (most recent call last):
  File "/usr/lib/python3.6/asyncio/base_events.py", line 1043, in create_server
    sock.bind(sa)
OSError: [Errno 98] Address already in use

During handling of the above exception, another exception occurred:

Traceback (most recent call last):
  File "server.py", line 97, in <module>
    web.run_app(app, host=ip_addr, port=port)
  File "/usr/lib/python3.6/site-packages/aiohttp/web.py", line 399, in run_app
    asyncio.gather(*server_creations, loop=loop)
  File "/usr/lib/python3.6/asyncio/base_events.py", line 466, in run_until_complete
    return future.result()
  File "/usr/lib/python3.6/asyncio/base_events.py", line 1047, in create_server
    % (sa, err.strerror.lower()))
OSError: [Errno 98] error while attempting to bind on address ('0.0.0.0', 8080): address already in use
Traceback (most recent call last):
  File "/usr/lib/python3.6/asyncio/base_events.py", line 1043, in create_server
    sock.bind(sa)
OSError: [Errno 98] Address already in use

During handling of the above exception, another exception occurred:

Traceback (most recent call last):
  File "server.py", line 97, in <module>
    web.run_app(app, host=ip_addr, port=port)
  File "/usr/lib/python3.6/site-packages/aiohttp/web.py", line 399, in run_app
    asyncio.gather(*server_creations, loop=loop)
  File "/usr/lib/python3.6/asyncio/base_events.py", line 466, in run_until_complete
    return future.result()
  File "/usr/lib/python3.6/asyncio/base_events.py", line 1047, in create_server
    % (sa, err.strerror.lower()))
OSError: [Errno 98] error while attempting to bind on address ('0.0.0.0', 8080): address already in use
